Traceback (most recent call last):
  File "/Users/antonplisnier/virtual_environments/automated_anki_notifications/lib/python3.12/site-packages/urllib3/connection.py", line 198, in _new_conn
    sock = connection.create_connection(
           ^^^^^^^^^^^^^^^^^^^^^^^^^^^^^
  File "/Users/antonplisnier/virtual_environments/automated_anki_notifications/lib/python3.12/site-packages/urllib3/util/connection.py", line 85, in create_connection
    raise err
  File "/Users/antonplisnier/virtual_environments/automated_anki_notifications/lib/python3.12/site-packages/urllib3/util/connection.py", line 73, in create_connection
    sock.connect(sa)
OSError: [Errno 51] Network is unreachable

The above exception was the direct cause of the following exception:

Traceback (most recent call last):
  File "/Users/antonplisnier/virtual_environments/automated_anki_notifications/lib/python3.12/site-packages/urllib3/connectionpool.py", line 793, in urlopen
    response = self._make_request(
               ^^^^^^^^^^^^^^^^^^^
  File "/Users/antonplisnier/virtual_environments/automated_anki_notifications/lib/python3.12/site-packages/urllib3/connectionpool.py", line 496, in _make_request
    conn.request(
  File "/Users/antonplisnier/virtual_environments/automated_anki_notifications/lib/python3.12/site-packages/urllib3/connection.py", line 400, in request
    self.endheaders()
  File "/usr/local/Cellar/python@3.12/3.12.1_1/Frameworks/Python.framework/Versions/3.12/lib/python3.12/http/client.py", line 1322, in endheaders
    self._send_output(message_body, encode_chunked=encode_chunked)
  File "/usr/local/Cellar/python@3.12/3.12.1_1/Frameworks/Python.framework/Versions/3.12/lib/python3.12/http/client.py", line 1081, in _send_output
    self.send(msg)
  File "/usr/local/Cellar/python@3.12/3.12.1_1/Frameworks/Python.framework/Versions/3.12/lib/python3.12/http/client.py", line 1025, in send
    self.connect()
  File "/Users/antonplisnier/virtual_environments/automated_anki_notifications/lib/python3.12/site-packages/urllib3/connection.py", line 238, in connect
    self.sock = self._new_conn()
                ^^^^^^^^^^^^^^^^
  File "/Users/antonplisnier/virtual_environments/automated_anki_notifications/lib/python3.12/site-packages/urllib3/connection.py", line 213, in _new_conn
    raise NewConnectionError(
urllib3.exceptions.NewConnectionError: <urllib3.connection.HTTPConnection object at 0x10eb7e930>: Failed to establish a new connection: [Errno 51] Network is unreachable

The above exception was the direct cause of the following exception:

Traceback (most recent call last):
  File "/Users/antonplisnier/virtual_environments/automated_anki_notifications/lib/python3.12/site-packages/requests/adapters.py", line 486, in send
    resp = conn.urlopen(
           ^^^^^^^^^^^^^
  File "/Users/antonplisnier/virtual_environments/automated_anki_notifications/lib/python3.12/site-packages/urllib3/connectionpool.py", line 847, in urlopen
    retries = retries.increment(
              ^^^^^^^^^^^^^^^^^^
  File "/Users/antonplisnier/virtual_environments/automated_anki_notifications/lib/python3.12/site-packages/urllib3/util/retry.py", line 515, in increment
    raise MaxRetryError(_pool, url, reason) from reason  # type: ignore[arg-type]
    ^^^^^^^^^^^^^^^^^^^^^^^^^^^^^^^^^^^^^^^^^^^^^^^^^^^
urllib3.exceptions.MaxRetryError: HTTPConnectionPool(host='1.1.1.1', port=80): Max retries exceeded with url: / (Caused by NewConnectionError('<urllib3.connection.HTTPConnection object at 0x10eb7e930>: Failed to establish a new connection: [Errno 51] Network is unreachable'))

During handling of the above exception, another exception occurred:

Traceback (most recent call last):
  File "/Users/antonplisnier/Desktop/Labour/.utilityThirdPartyCodebases/ankiConnect/main.py", line 16, in <module>
    exit(main())
         ^^^^^^
  File "/Users/antonplisnier/Desktop/Labour/.utilityThirdPartyCodebases/ankiConnect/main.py", line 9, in main
    if has_internet_connection():
       ^^^^^^^^^^^^^^^^^^^^^^^^^
  File "/Users/antonplisnier/Desktop/Labour/.utilityThirdPartyCodebases/ankiConnect/helpers.py", line 12, in has_internet_connection
    get(f'http://{ip}', timeout=1)     
    ^^^^^^^^^^^^^^^^^^^^^^^^^^^^^^
  File "/Users/antonplisnier/virtual_environments/automated_anki_notifications/lib/python3.12/site-packages/requests/api.py", line 73, in get
    return request("get", url, params=params, **kwargs)
           ^^^^^^^^^^^^^^^^^^^^^^^^^^^^^^^^^^^^^^^^^^^^
  File "/Users/antonplisnier/virtual_environments/automated_anki_notifications/lib/python3.12/site-packages/requests/api.py", line 59, in request
    return session.request(method=method, url=url, **kwargs)
           ^^^^^^^^^^^^^^^^^^^^^^^^^^^^^^^^^^^^^^^^^^^^^^^^^
  File "/Users/antonplisnier/virtual_environments/automated_anki_notifications/lib/python3.12/site-packages/requests/sessions.py", line 589, in request
    resp = self.send(prep, **send_kwargs)
           ^^^^^^^^^^^^^^^^^^^^^^^^^^^^^^
  File "/Users/antonplisnier/virtual_environments/automated_anki_notifications/lib/python3.12/site-packages/requests/sessions.py", line 703, in send
    r = adapter.send(request, **kwargs)
        ^^^^^^^^^^^^^^^^^^^^^^^^^^^^^^^
  File "/Users/antonplisnier/virtual_environments/automated_anki_notifications/lib/python3.12/site-packages/requests/adapters.py", line 519, in send
    raise ConnectionError(e, request=request)
requests.exceptions.ConnectionError: HTTPConnectionPool(host='1.1.1.1', port=80): Max retries exceeded with url: / (Caused by NewConnectionError('<urllib3.connection.HTTPConnection object at 0x10eb7e930>: Failed to establish a new connection: [Errno 51] Network is unreachable'))
Traceback (most recent call last):
  File "/Users/antonplisnier/virtual_environments/automated_anki_notifications/lib/python3.12/site-packages/urllib3/connection.py", line 198, in _new_conn
    sock = connection.create_connection(
           ^^^^^^^^^^^^^^^^^^^^^^^^^^^^^
  File "/Users/antonplisnier/virtual_environments/automated_anki_notifications/lib/python3.12/site-packages/urllib3/util/connection.py", line 85, in create_connection
    raise err
  File "/Users/antonplisnier/virtual_environments/automated_anki_notifications/lib/python3.12/site-packages/urllib3/util/connection.py", line 73, in create_connection
    sock.connect(sa)
OSError: [Errno 51] Network is unreachable

The above exception was the direct cause of the following exception:

Traceback (most recent call last):
  File "/Users/antonplisnier/virtual_environments/automated_anki_notifications/lib/python3.12/site-packages/urllib3/connectionpool.py", line 793, in urlopen
    response = self._make_request(
               ^^^^^^^^^^^^^^^^^^^
  File "/Users/antonplisnier/virtual_environments/automated_anki_notifications/lib/python3.12/site-packages/urllib3/connectionpool.py", line 496, in _make_request
    conn.request(
  File "/Users/antonplisnier/virtual_environments/automated_anki_notifications/lib/python3.12/site-packages/urllib3/connection.py", line 400, in request
    self.endheaders()
  File "/usr/local/Cellar/python@3.12/3.12.1_1/Frameworks/Python.framework/Versions/3.12/lib/python3.12/http/client.py", line 1322, in endheaders
    self._send_output(message_body, encode_chunked=encode_chunked)
  File "/usr/local/Cellar/python@3.12/3.12.1_1/Frameworks/Python.framework/Versions/3.12/lib/python3.12/http/client.py", line 1081, in _send_output
    self.send(msg)
  File "/usr/local/Cellar/python@3.12/3.12.1_1/Frameworks/Python.framework/Versions/3.12/lib/python3.12/http/client.py", line 1025, in send
    self.connect()
  File "/Users/antonplisnier/virtual_environments/automated_anki_notifications/lib/python3.12/site-packages/urllib3/connection.py", line 238, in connect
    self.sock = self._new_conn()
                ^^^^^^^^^^^^^^^^
  File "/Users/antonplisnier/virtual_environments/automated_anki_notifications/lib/python3.12/site-packages/urllib3/connection.py", line 213, in _new_conn
    raise NewConnectionError(
urllib3.exceptions.NewConnectionError: <urllib3.connection.HTTPConnection object at 0x104176930>: Failed to establish a new connection: [Errno 51] Network is unreachable

The above exception was the direct cause of the following exception:

Traceback (most recent call last):
  File "/Users/antonplisnier/virtual_environments/automated_anki_notifications/lib/python3.12/site-packages/requests/adapters.py", line 486, in send
    resp = conn.urlopen(
           ^^^^^^^^^^^^^
  File "/Users/antonplisnier/virtual_environments/automated_anki_notifications/lib/python3.12/site-packages/urllib3/connectionpool.py", line 847, in urlopen
    retries = retries.increment(
              ^^^^^^^^^^^^^^^^^^
  File "/Users/antonplisnier/virtual_environments/automated_anki_notifications/lib/python3.12/site-packages/urllib3/util/retry.py", line 515, in increment
    raise MaxRetryError(_pool, url, reason) from reason  # type: ignore[arg-type]
    ^^^^^^^^^^^^^^^^^^^^^^^^^^^^^^^^^^^^^^^^^^^^^^^^^^^
urllib3.exceptions.MaxRetryError: HTTPConnectionPool(host='1.1.1.1', port=80): Max retries exceeded with url: / (Caused by NewConnectionError('<urllib3.connection.HTTPConnection object at 0x104176930>: Failed to establish a new connection: [Errno 51] Network is unreachable'))

During handling of the above exception, another exception occurred:

Traceback (most recent call last):
  File "/Users/antonplisnier/Desktop/Labour/.utilityThirdPartyCodebases/ankiConnect/main.py", line 16, in <module>
    exit(main())
         ^^^^^^
  File "/Users/antonplisnier/Desktop/Labour/.utilityThirdPartyCodebases/ankiConnect/main.py", line 9, in main
    if has_internet_connection():
       ^^^^^^^^^^^^^^^^^^^^^^^^^
  File "/Users/antonplisnier/Desktop/Labour/.utilityThirdPartyCodebases/ankiConnect/helpers.py", line 12, in has_internet_connection
    get(f'http://{ip}', timeout=1)     
    ^^^^^^^^^^^^^^^^^^^^^^^^^^^^^^
  File "/Users/antonplisnier/virtual_environments/automated_anki_notifications/lib/python3.12/site-packages/requests/api.py", line 73, in get
    return request("get", url, params=params, **kwargs)
           ^^^^^^^^^^^^^^^^^^^^^^^^^^^^^^^^^^^^^^^^^^^^
  File "/Users/antonplisnier/virtual_environments/automated_anki_notifications/lib/python3.12/site-packages/requests/api.py", line 59, in request
    return session.request(method=method, url=url, **kwargs)
           ^^^^^^^^^^^^^^^^^^^^^^^^^^^^^^^^^^^^^^^^^^^^^^^^^
  File "/Users/antonplisnier/virtual_environments/automated_anki_notifications/lib/python3.12/site-packages/requests/sessions.py", line 589, in request
    resp = self.send(prep, **send_kwargs)
           ^^^^^^^^^^^^^^^^^^^^^^^^^^^^^^
  File "/Users/antonplisnier/virtual_environments/automated_anki_notifications/lib/python3.12/site-packages/requests/sessions.py", line 703, in send
    r = adapter.send(request, **kwargs)
        ^^^^^^^^^^^^^^^^^^^^^^^^^^^^^^^
  File "/Users/antonplisnier/virtual_environments/automated_anki_notifications/lib/python3.12/site-packages/requests/adapters.py", line 519, in send
    raise ConnectionError(e, request=request)
requests.exceptions.ConnectionError: HTTPConnectionPool(host='1.1.1.1', port=80): Max retries exceeded with url: / (Caused by NewConnectionError('<urllib3.connection.HTTPConnection object at 0x104176930>: Failed to establish a new connection: [Errno 51] Network is unreachable'))
